[42.640686035] 2019-01-17 17:36:54,145 - INFO - launcher: Starting sanity checks
[42.640686035] 2019-01-17 17:36:54,145 - INFO - launcher: Checking for Python 3.5+
[42.640686035] 2019-01-17 17:36:54,145 - INFO - launcher: Checking console encoding
[42.640686035] 2019-01-17 17:36:54,145 - INFO - launcher: Setting console encoding to UTF-8
[43.622493744] 2019-01-17 17:36:54,146 - INFO - launcher: Ensuring we're in the right environment
[45.623064041] 2019-01-17 17:36:54,148 - INFO - launcher: Adding local bins/ folder to path
[636.897325516] 2019-01-17 17:36:54,740 - INFO - launcher: Required checks passed.
[651.448726654] 2019-01-17 17:36:54,754 - INFO - launcher: Optional checks passed.

######################### PRE-RUN SANITY CHECKS PASSED #########################

[1.6050980091094971] 2019-01-17 17:36:55,708 - WARNING - musicbot.config | In config.py::MainThread(12076), line 113 in run_checks: i18n file does not exist. Trying to fallback to config/i18n/en.json.
[1.6050980091094971] 2019-01-17 17:36:55,708 - INFO - musicbot.config | In config.py::MainThread(12076), line 124 in run_checks: Using i18n: config/i18n/en.json
[1.6100964546203613] 2019-01-17 17:36:55,713 - DEBUG - musicbot.json | In json.py::MainThread(12076), line 8 in __init__: Init JSON obj with config/i18n/en.json
[2.1183683872222900] 2019-01-17 17:36:56,221 - DEBUG - musicbot.bot | In bot.py::MainThread(12076), line 223 in _setup_logging: Set logging level to INFO
[2.1183683872222900] 2019-01-17 17:36:56,221 - INFO - musicbot.bot | In bot.py::MainThread(12076), line 83 in __init__: Starting MusicBot 1.9.8_1
[2.1193490028381348] 2019-01-17 17:36:56,222 - INFO - musicbot.bot | In bot.py::MainThread(12076), line 89 in __init__: Loaded autoplaylist with 3055 entries
[5.7226474285125732] 2019-01-17 17:36:59,825 - DEBUG - musicbot.bot | In bot.py::MainThread(12076), line 913 in on_ready: Connection established, ready to go.
[5.7226474285125732] 2019-01-17 17:36:59,825 - DEBUG - musicbot.bot | In bot.py::MainThread(12076), line 334 in _cache_app_info: Caching app info
[6.0108907222747803] 2019-01-17 17:37:00,114 - DEBUG - musicbot.bot | In bot.py::MainThread(12076), line 735 in _scheck_ensure_env: Ensuring data folders exist
[6.0347080230712891] 2019-01-17 17:37:00,137 - DEBUG - musicbot.bot | In bot.py::MainThread(12076), line 751 in _scheck_server_permissions: Checking server permissions
[6.0347080230712891] 2019-01-17 17:37:00,137 - DEBUG - musicbot.bot | In bot.py::MainThread(12076), line 755 in _scheck_autoplaylist: Auditing autoplaylist
[6.0347080230712891] 2019-01-17 17:37:00,137 - DEBUG - musicbot.bot | In bot.py::MainThread(12076), line 759 in _scheck_configs: Validating config
[6.0347080230712891] 2019-01-17 17:37:00,137 - DEBUG - musicbot.config | In config.py::MainThread(12076), line 213 in async_validate: Validating options...
[6.0347080230712891] 2019-01-17 17:37:00,137 - DEBUG - musicbot.bot | In bot.py::MainThread(12076), line 762 in _scheck_configs: Validating permissions config
[6.0347080230712891] 2019-01-17 17:37:00,137 - DEBUG - musicbot.permissions | In permissions.py::MainThread(12076), line 65 in async_validate: Validating permissions...
[6.0347080230712891] 2019-01-17 17:37:00,137 - INFO - musicbot.bot | In bot.py::MainThread(12076), line 930 in on_ready: Connected: 533266784229523456/Test Music Bot#3711
[6.0361773967742920] 2019-01-17 17:37:00,139 - INFO - musicbot.bot | In bot.py::MainThread(12076), line 938 in on_ready: Owner:     254851632481697792/Thunder#8077

[6.0369398593902588] 2019-01-17 17:37:00,140 - INFO - musicbot.bot | In bot.py::MainThread(12076), line 941 in on_ready: Guild List:
[6.0376670360565186] 2019-01-17 17:37:00,140 - INFO - musicbot.bot | In bot.py::MainThread(12076), line 944 in on_ready:  - ThunderServer
[6.0376670360565186] 2019-01-17 17:37:00,140 - INFO - musicbot.bot | In bot.py::MainThread(12076), line 990 in on_ready: Not bound to any text channels
[6.0386691093444824] 2019-01-17 17:37:00,141 - INFO - musicbot.bot | In bot.py::MainThread(12076), line 1003 in on_ready: Autojoining voice chanels:
[6.0386691093444824] 2019-01-17 17:37:00,141 - INFO - musicbot.bot | In bot.py::MainThread(12076), line 1004 in <listcomp>:  - ThunderServer/Music Chill
[6.0396687984466553] 2019-01-17 17:37:00,142 - INFO - musicbot.bot | In bot.py::MainThread(12076), line 276 in _join_startup_channels: Attempting to join ThunderServer/Music Chill
[6.8094666004180908] 2019-01-17 17:37:00,912 - INFO - musicbot.bot | In bot.py::MainThread(12076), line 292 in _join_startup_channels: Joined ThunderServer/Music Chill
[6.8104696273803711] 2019-01-17 17:37:00,913 - DEBUG - musicbot.bot | In bot.py::MainThread(12076), line 505 in on_player_stop: Running on_player_stop
[23.6013743877410889] 2019-01-17 17:37:17,704 - ERROR - musicbot.bot | In bot.py::MainThread(12076), line 901 in on_error: Exception in on_voice_state_update
Traceback (most recent call last):
  File "C:\Users\Lucas\Desktop\rhinobot_heroku-master\musicbot\bot.py", line 864, in run
    self.loop.run_until_complete(self.start(*self.config.auth))
  File "C:\Users\Lucas\AppData\Local\Programs\Python\Python35\lib\asyncio\base_events.py", line 454, in run_until_complete
    self.run_forever()
  File "C:\Users\Lucas\AppData\Local\Programs\Python\Python35\lib\asyncio\base_events.py", line 421, in run_forever
    self._run_once()
  File "C:\Users\Lucas\AppData\Local\Programs\Python\Python35\lib\asyncio\base_events.py", line 1389, in _run_once
    event_list = self._selector.select(timeout)
  File "C:\Users\Lucas\AppData\Local\Programs\Python\Python35\lib\asyncio\windows_events.py", line 414, in select
    self._poll(timeout)
  File "C:\Users\Lucas\AppData\Local\Programs\Python\Python35\lib\asyncio\windows_events.py", line 668, in _poll
    status = _overlapped.GetQueuedCompletionStatus(self._iocp, ms)
KeyboardInterrupt

During handling of the above exception, another exception occurred:

Traceback (most recent call last):
  File "C:\Users\Lucas\AppData\Local\Programs\Python\Python35\lib\site-packages\discord\client.py", line 227, in _run_event
    await coro(*args, **kwargs)
  File "C:\Users\Lucas\Desktop\rhinobot_heroku-master\musicbot\bot.py", line 2796, in on_voice_state_update
    player = await self.get_player(channel)
  File "C:\Users\Lucas\Desktop\rhinobot_heroku-master\musicbot\bot.py", line 425, in get_player
    'Use %ssummon to summon it to your voice channel.' % self.config.command_prefix)
musicbot.exceptions.CommandError: The bot is not in a voice channel.  Use <<summon to summon it to your voice channel.
